Workbook

Sheet Fake Live Dashboard
A1: IT Simplification — FY27 Cost-out Dashboard
A2: Actual savings achieved, remaining opportunity and timing by quarter
A4: V1 BUDGET | D4: ENTERED RENEWAL PRICE | G4: NET IDENTIFIED COSTOUT | I4: FINALISED POSITIVE COSTOUT
A5: =B24 -> 23692506 | D5: =C24 -> 22962976 | G5: =D24 -> 728974.63 | I5: =E24 -> 320983.41
A7: ="The tracked V1 budget is "&TEXT(A5,"$#,##0")&" and entered renewal prices total "&TEXT(D5,"$#,##0")&". The signed net identified costout in Column J is "&TEXT(G5,"$#,##0")&". Of the "&TEXT(E24+F24,"$#,##0")&" gross positive costout identified, "&TEXT(I5,"$#,##0")&" is finalised ("&TEXT(IFERROR(E24/(E24+F24),0),"0.0%")&"); "&TEXT(G24,"$#,##0")&" is separately classified as budget variance / reclassification." -> The tracked V1 budget is $23,692,506 and entered renewal prices total $22,962,976. The signed net identified costout in Column J is $728,975. Of the $1,009,252 gross positive costout identified, $320,983 is finalised (31.8%); $280,277 is separately classified as budget variance / reclassification.
A10: QUARTERLY BUDGET, RENEWAL AND COSTOUT OUTLOOK
A11: Metric | B11: Q1 FY27 | C11: Q2 FY27 | D11: Q3 FY27 | E11: Q4 FY27 | F11: Unscheduled | G11: FY27 Total
A12: V1 budget | B12: {=SUM(SUMIFS('Fake Simplified View'!$F$2:$F$143,'Fake Simplified View'!$D$2:$D$143,{"Licensing","Consumption","New spend","Microsoft"},'Fake Simplified View'!$E$2:$E$143,">="&DATE(2026,7,1),'Fake Simplified View'!$E$2:$E$143,"<"&DATE(2026,10,1)))} -> 844008.17 | C12: {=SUM(SUMIFS('Fake Simplified View'!$F$2:$F$143,'Fake Simplified View'!$D$2:$D$143,{"Licensing","Consumption","New spend","Microsoft"},'Fake Simplified View'!$E$2:$E$143,">="&DATE(2026,10,1),'Fake Simplified View'!$E$2:$E$143,"<"&DATE(2027,1,1)))} -> 3477136.3 | D12: {=SUM(SUMIFS('Fake Simplified View'!$F$2:$F$143,'Fake Simplified View'!$D$2:$D$143,{"Licensing","Consumption","New spend","Microsoft"},'Fake Simplified View'!$E$2:$E$143,">="&DATE(2027,1,1),'Fake Simplified View'!$E$2:$E$143,"<"&DATE(2027,4,1)))} -> 1175842.5 | E12: {=SUM(SUMIFS('Fake Simplified View'!$F$2:$F$143,'Fake Simplified View'!$D$2:$D$143,{"Licensing","Consumption","New spend","Microsoft"},'Fake Simplified View'!$E$2:$E$143,">="&DATE(2027,4,1),'Fake Simplified View'!$E$2:$E$143,"<"&DATE(2027,7,1)))} -> 1272025.9 | F12: {=SUMPRODUCT(--ISNUMBER(MATCH('Fake Simplified View'!$D$2:$D$143,{"Licensing","Consumption","New spend","Microsoft"},0)),--IF(ISNUMBER('Fake Simplified View'!$E$2:$E$143),(('Fake Simplified View'!$E$2:$E$143<DATE(2026,7,1))+('Fake Simplified View'!$E$2:$E$143>=DATE(2027,7,1))>0),TRUE),'Fake Simplified View'!$F$2:$F$143)} -> 16923494 | G12: =B24 -> 23692506
A13: Entered renewal price | B13: {=SUM(SUMIFS('Fake Simplified View'!$G$2:$G$143,'Fake Simplified View'!$D$2:$D$143,{"Licensing","Consumption","New spend","Microsoft"},'Fake Simplified View'!$E$2:$E$143,">="&DATE(2026,7,1),'Fake Simplified View'!$E$2:$E$143,"<"&DATE(2026,10,1)))} -> 588167.13 | C13: {=SUM(SUMIFS('Fake Simplified View'!$G$2:$G$143,'Fake Simplified View'!$D$2:$D$143,{"Licensing","Consumption","New spend","Microsoft"},'Fake Simplified View'!$E$2:$E$143,">="&DATE(2026,10,1),'Fake Simplified View'!$E$2:$E$143,"<"&DATE(2027,1,1)))} -> 3379516.7 | D13: {=SUM(SUMIFS('Fake Simplified View'!$G$2:$G$143,'Fake Simplified View'!$D$2:$D$143,{"Licensing","Consumption","New spend","Microsoft"},'Fake Simplified View'!$E$2:$E$143,">="&DATE(2027,1,1),'Fake Simplified View'!$E$2:$E$143,"<"&DATE(2027,4,1)))} -> 1172578.4 | E13: {=SUM(SUMIFS('Fake Simplified View'!$G$2:$G$143,'Fake Simplified View'!$D$2:$D$143,{"Licensing","Consumption","New spend","Microsoft"},'Fake Simplified View'!$E$2:$E$143,">="&DATE(2027,4,1),'Fake Simplified View'!$E$2:$E$143,"<"&DATE(2027,7,1)))} -> 1264749.7 | F13: {=SUMPRODUCT(--ISNUMBER(MATCH('Fake Simplified View'!$D$2:$D$143,{"Licensing","Consumption","New spend","Microsoft"},0)),--IF(ISNUMBER('Fake Simplified View'!$E$2:$E$143),(('Fake Simplified View'!$E$2:$E$143<DATE(2026,7,1))+('Fake Simplified View'!$E$2:$E$143>=DATE(2027,7,1))>0),TRUE),'Fake Simplified View'!$G$2:$G$143)} -> 16557964 | G13: =C24 -> 22962976
A14: Net identified costout | B14: {=SUM(SUMIFS('Fake Simplified View'!$H$2:$H$143,'Fake Simplified View'!$D$2:$D$143,{"Licensing","Consumption","New spend","Microsoft"},'Fake Simplified View'!$E$2:$E$143,">="&DATE(2026,7,1),'Fake Simplified View'!$E$2:$E$143,"<"&DATE(2026,10,1)))} -> 255841.04 | C14: {=SUM(SUMIFS('Fake Simplified View'!$H$2:$H$143,'Fake Simplified View'!$D$2:$D$143,{"Licensing","Consumption","New spend","Microsoft"},'Fake Simplified View'!$E$2:$E$143,">="&DATE(2026,10,1),'Fake Simplified View'!$E$2:$E$143,"<"&DATE(2027,1,1)))} -> 97619.637 | D14: {=SUM(SUMIFS('Fake Simplified View'!$H$2:$H$143,'Fake Simplified View'!$D$2:$D$143,{"Licensing","Consumption","New spend","Microsoft"},'Fake Simplified View'!$E$2:$E$143,">="&DATE(2027,1,1),'Fake Simplified View'!$E$2:$E$143,"<"&DATE(2027,4,1)))} -> 2708.36 | E14: {=SUM(SUMIFS('Fake Simplified View'!$H$2:$H$143,'Fake Simplified View'!$D$2:$D$143,{"Licensing","Consumption","New spend","Microsoft"},'Fake Simplified View'!$E$2:$E$143,">="&DATE(2027,4,1),'Fake Simplified View'!$E$2:$E$143,"<"&DATE(2027,7,1)))} -> 7276.18 | F14: {=SUMPRODUCT(--ISNUMBER(MATCH('Fake Simplified View'!$D$2:$D$143,{"Licensing","Consumption","New spend","Microsoft"},0)),--IF(ISNUMBER('Fake Simplified View'!$E$2:$E$143),(('Fake Simplified View'!$E$2:$E$143<DATE(2026,7,1))+('Fake Simplified View'!$E$2:$E$143>=DATE(2027,7,1))>0),TRUE),'Fake Simplified View'!$H$2:$H$143)} -> 365529.41 | G14: =D24 -> 728974.63
A15: Finalised positive costout | B15: {=SUM(SUMIFS('Fake Simplified View'!$H$2:$H$143,'Fake Simplified View'!$D$2:$D$143,{"Licensing","Consumption","New spend","Microsoft"},'Fake Simplified View'!$C$2:$C$143,"Y",'Fake Simplified View'!$H$2:$H$143,">0",'Fake Simplified View'!$E$2:$E$143,">="&DATE(2026,7,1),'Fake Simplified View'!$E$2:$E$143,"<"&DATE(2026,10,1)))} -> 27820.323 | C15: {=SUM(SUMIFS('Fake Simplified View'!$H$2:$H$143,'Fake Simplified View'!$D$2:$D$143,{"Licensing","Consumption","New spend","Microsoft"},'Fake Simplified View'!$C$2:$C$143,"Y",'Fake Simplified View'!$H$2:$H$143,">0",'Fake Simplified View'!$E$2:$E$143,">="&DATE(2026,10,1),'Fake Simplified View'!$E$2:$E$143,"<"&DATE(2027,1,1)))} -> 22095.13 | D15: {=SUM(SUMIFS('Fake Simplified View'!$H$2:$H$143,'Fake Simplified View'!$D$2:$D$143,{"Licensing","Consumption","New spend","Microsoft"},'Fake Simplified View'!$C$2:$C$143,"Y",'Fake Simplified View'!$H$2:$H$143,">0",'Fake Simplified View'!$E$2:$E$143,">="&DATE(2027,1,1),'Fake Simplified View'!$E$2:$E$143,"<"&DATE(2027,4,1)))} -> 0 | E15: {=SUM(SUMIFS('Fake Simplified View'!$H$2:$H$143,'Fake Simplified View'!$D$2:$D$143,{"Licensing","Consumption","New spend","Microsoft"},'Fake Simplified View'!$C$2:$C$143,"Y",'Fake Simplified View'!$H$2:$H$143,">0",'Fake Simplified View'!$E$2:$E$143,">="&DATE(2027,4,1),'Fake Simplified View'!$E$2:$E$143,"<"&DATE(2027,7,1)))} -> 0 | F15: {=SUMPRODUCT(--ISNUMBER(MATCH('Fake Simplified View'!$D$2:$D$143,{"Licensing","Consumption","New spend","Microsoft"},0)),--IF(ISNUMBER('Fake Simplified View'!$E$2:$E$143),(('Fake Simplified View'!$E$2:$E$143<DATE(2026,7,1))+('Fake Simplified View'!$E$2:$E$143>=DATE(2027,7,1))>0),TRUE),--(UPPER(TRIM('Fake Simplified View'!$C$2:$C$143))="Y"),--('Fake Simplified View'!$H$2:$H$143>0),'Fake Simplified View'!$H$2:$H$143)} -> 271067.96 | G15: =E24 -> 320983.41
A16: Unfinalised positive costout | B16: {=SUM(SUMIFS('Fake Simplified View'!$H$2:$H$143,'Fake Simplified View'!$D$2:$D$143,{"Licensing","Consumption","New spend","Microsoft"},'Fake Simplified View'!$C$2:$C$143,"<>Y",'Fake Simplified View'!$H$2:$H$143,">0",'Fake Simplified View'!$E$2:$E$143,">="&DATE(2026,7,1),'Fake Simplified View'!$E$2:$E$143,"<"&DATE(2026,10,1)))} -> 230609.96 | C16: {=SUM(SUMIFS('Fake Simplified View'!$H$2:$H$143,'Fake Simplified View'!$D$2:$D$143,{"Licensing","Consumption","New spend","Microsoft"},'Fake Simplified View'!$C$2:$C$143,"<>Y",'Fake Simplified View'!$H$2:$H$143,">0",'Fake Simplified View'!$E$2:$E$143,">="&DATE(2026,10,1),'Fake Simplified View'!$E$2:$E$143,"<"&DATE(2027,1,1)))} -> 111226.91 | D16: {=SUM(SUMIFS('Fake Simplified View'!$H$2:$H$143,'Fake Simplified View'!$D$2:$D$143,{"Licensing","Consumption","New spend","Microsoft"},'Fake Simplified View'!$C$2:$C$143,"<>Y",'Fake Simplified View'!$H$2:$H$143,">0",'Fake Simplified View'!$E$2:$E$143,">="&DATE(2027,1,1),'Fake Simplified View'!$E$2:$E$143,"<"&DATE(2027,4,1)))} -> 3088.36 | E16: {=SUM(SUMIFS('Fake Simplified View'!$H$2:$H$143,'Fake Simplified View'!$D$2:$D$143,{"Licensing","Consumption","New spend","Microsoft"},'Fake Simplified View'!$C$2:$C$143,"<>Y",'Fake Simplified View'!$H$2:$H$143,">0",'Fake Simplified View'!$E$2:$E$143,">="&DATE(2027,4,1),'Fake Simplified View'!$E$2:$E$143,"<"&DATE(2027,7,1)))} -> 48881.52 | F16: {=SUMPRODUCT(--ISNUMBER(MATCH('Fake Simplified View'!$D$2:$D$143,{"Licensing","Consumption","New spend","Microsoft"},0)),--IF(ISNUMBER('Fake Simplified View'!$E$2:$E$143),(('Fake Simplified View'!$E$2:$E$143<DATE(2026,7,1))+('Fake Simplified View'!$E$2:$E$143>=DATE(2027,7,1))>0),TRUE),--(UPPER(TRIM('Fake Simplified View'!$C$2:$C$143))<>"Y"),--('Fake Simplified View'!$H$2:$H$143>0),'Fake Simplified View'!$H$2:$H$143)} -> 294461.45 | G16: =F24 -> 688268.2
A17: Budget variance / reclassification | B17: {=-SUM(SUMIFS('Fake Simplified View'!$H$2:$H$143,'Fake Simplified View'!$D$2:$D$143,{"Licensing","Consumption","New spend","Microsoft"},'Fake Simplified View'!$H$2:$H$143,"<0",'Fake Simplified View'!$E$2:$E$143,">="&DATE(2026,7,1),'Fake Simplified View'!$E$2:$E$143,"<"&DATE(2026,10,1)))} -> 2589.24 | C17: {=-SUM(SUMIFS('Fake Simplified View'!$H$2:$H$143,'Fake Simplified View'!$D$2:$D$143,{"Licensing","Consumption","New spend","Microsoft"},'Fake Simplified View'!$H$2:$H$143,"<0",'Fake Simplified View'!$E$2:$E$143,">="&DATE(2026,10,1),'Fake Simplified View'!$E$2:$E$143,"<"&DATE(2027,1,1)))} -> 35702.4 | D17: {=-SUM(SUMIFS('Fake Simplified View'!$H$2:$H$143,'Fake Simplified View'!$D$2:$D$143,{"Licensing","Consumption","New spend","Microsoft"},'Fake Simplified View'!$H$2:$H$143,"<0",'Fake Simplified View'!$E$2:$E$143,">="&DATE(2027,1,1),'Fake Simplified View'!$E$2:$E$143,"<"&DATE(2027,4,1)))} -> 380 | E17: {=-SUM(SUMIFS('Fake Simplified View'!$H$2:$H$143,'Fake Simplified View'!$D$2:$D$143,{"Licensing","Consumption","New spend","Microsoft"},'Fake Simplified View'!$H$2:$H$143,"<0",'Fake Simplified View'!$E$2:$E$143,">="&DATE(2027,4,1),'Fake Simplified View'!$E$2:$E$143,"<"&DATE(2027,7,1)))} -> 41605.34 | F17: {=-SUMPRODUCT(--ISNUMBER(MATCH('Fake Simplified View'!$D$2:$D$143,{"Licensing","Consumption","New spend","Microsoft"},0)),--IF(ISNUMBER('Fake Simplified View'!$E$2:$E$143),(('Fake Simplified View'!$E$2:$E$143<DATE(2026,7,1))+('Fake Simplified View'!$E$2:$E$143>=DATE(2027,7,1))>0),TRUE),--('Fake Simplified View'!$H$2:$H$143<0),'Fake Simplified View'!$H$2:$H$143)} -> 200000.01 | G17: =G24 -> 280276.99
A19: CATEGORY BUDGET, RENEWAL AND COSTOUT OUTLOOK
A20: Category | B20: V1 budget | C20: Entered renewal price | D20: Net identified costout | E20: Finalised positive costout | F20: Unfinalised positive costout | G20: Budget variance / reclassification
A21: Licensing | B21: =SUMIFS('Fake Simplified View'!$F$2:$F$143,'Fake Simplified View'!$D$2:$D$143,$A21) -> 15574045 | C21: =SUMIFS('Fake Simplified View'!$G$2:$G$143,'Fake Simplified View'!$D$2:$D$143,$A21) -> 14844915 | D21: =SUMIFS('Fake Simplified View'!$H$2:$H$143,'Fake Simplified View'!$D$2:$D$143,$A21) -> 728574.63 | E21: =SUMIFS('Fake Simplified View'!$H$2:$H$143,'Fake Simplified View'!$D$2:$D$143,$A21,'Fake Simplified View'!$C$2:$C$143,"Y",'Fake Simplified View'!$H$2:$H$143,">0") -> 320983.41 | F21: =SUMIFS('Fake Simplified View'!$H$2:$H$143,'Fake Simplified View'!$D$2:$D$143,$A21,'Fake Simplified View'!$C$2:$C$143,"<>Y",'Fake Simplified View'!$H$2:$H$143,">0") -> 687868.2 | G21: =-SUMIFS('Fake Simplified View'!$H$2:$H$143,'Fake Simplified View'!$D$2:$D$143,$A21,'Fake Simplified View'!$H$2:$H$143,"<0") -> 280276.99 | I21: Net identified costout: Overall expected reduction based on all values currently entered
A22: Consumption | B22: =SUMIFS('Fake Simplified View'!$F$2:$F$143,'Fake Simplified View'!$D$2:$D$143,$A22) -> 7659712.8 | C22: =SUMIFS('Fake Simplified View'!$G$2:$G$143,'Fake Simplified View'!$D$2:$D$143,$A22) -> 7659312.8 | D22: =SUMIFS('Fake Simplified View'!$H$2:$H$143,'Fake Simplified View'!$D$2:$D$143,$A22) -> 400.00259 | E22: =SUMIFS('Fake Simplified View'!$H$2:$H$143,'Fake Simplified View'!$D$2:$D$143,$A22,'Fake Simplified View'!$C$2:$C$143,"Y",'Fake Simplified View'!$H$2:$H$143,">0") -> 0 | F22: =SUMIFS('Fake Simplified View'!$H$2:$H$143,'Fake Simplified View'!$D$2:$D$143,$A22,'Fake Simplified View'!$C$2:$C$143,"<>Y",'Fake Simplified View'!$H$2:$H$143,">0") -> 400.00259 | G22: =-SUMIFS('Fake Simplified View'!$H$2:$H$143,'Fake Simplified View'!$D$2:$D$143,$A22,'Fake Simplified View'!$H$2:$H$143,"<0") -> 0 | I22: Finalised positive costout: Savings confirmed/completed
A23: New Spend | B23: =SUMIFS('Fake Simplified View'!$F$2:$F$143,'Fake Simplified View'!$D$2:$D$143,$A23) -> 458748.67 | C23: =SUMIFS('Fake Simplified View'!$G$2:$G$143,'Fake Simplified View'!$D$2:$D$143,$A23) -> 458748.67 | D23: =SUMIFS('Fake Simplified View'!$H$2:$H$143,'Fake Simplified View'!$D$2:$D$143,$A23) -> 0 | E23: =SUMIFS('Fake Simplified View'!$H$2:$H$143,'Fake Simplified View'!$D$2:$D$143,$A23,'Fake Simplified View'!$C$2:$C$143,"Y",'Fake Simplified View'!$H$2:$H$143,">0") -> 0 | F23: =SUMIFS('Fake Simplified View'!$H$2:$H$143,'Fake Simplified View'!$D$2:$D$143,$A23,'Fake Simplified View'!$C$2:$C$143,"<>Y",'Fake Simplified View'!$H$2:$H$143,">0") -> 0 | G23: =-SUMIFS('Fake Simplified View'!$H$2:$H$143,'Fake Simplified View'!$D$2:$D$143,$A23,'Fake Simplified View'!$H$2:$H$143,"<0") -> 0 | I23: Unfinalised positive costout: Savings pipeline - not guaranteed savings
A24: Total | B24: =SUM(B21:B23) -> 23692506 | C24: =SUM(C21:C23) -> 22962976 | D24: =SUM(D21:D23) -> 728974.63 | E24: =SUM(E21:E23) -> 320983.41 | F24: =SUM(F21:F23) -> 688268.2 | G24: =SUM(G21:G23) -> 280276.99
A26: {=_xlfn._LONGTEXT("Definitions: Net identified costout = the signed total of Column J across Licensing, Consumption, New Spend and Microsoft. Gross positive costout = positive Column J only. Finalised positive costout = positive Column J where Finalised? is Y. Budget varian","ce / reclassification = the absolute value of negative Column J. Entered renewal price sums values currently populated in Column I. Data note: ")&SUMPRODUCT(--ISNUMBER(MATCH('Fake Simplified View'!$D$2:$D$143,{"Licensing","Consumption","New spend","Microsoft"},0)),--('Fake Simplified View'!$G$2:$G$143=""))&" tracked renewal-price cells are blank, covering "&TEXT(SUMPRODUCT(--ISNUMBER(MATCH('Fake Simplified View'!$D$2:$D$143,{"Licensing","Consumption","New spend","Microsoft"},0)),--('Fake Simplified View'!$G$2:$G$143=""),'Fake Simplified View'!$F$2:$F$143),"$#,##0")&" of V1 budget."} -> Definitions: Net identified costout = the signed total of Column J across Licensing, Consumption, New Spend and Microsoft. Gross positive costout = positive Column J only. Finalised positive costout = positive Column J where Finalised? is Y. Budget variance / reclassification = the absolute value of negative Column J. Entered renewal price sums values currently populated in Column I. Data note: 8 tracked renewal-price cells are blank, covering $91,963 of V1 budget.
A30: Licensing cost-out to date
A31: {=_xlfn.LET(_xlpm.committed,_xlfn._xlws.FILTER(_xlfn.CHOOSECOLS('Fake Simplified View'!A2:H143,1,2,6,7,8),('Fake Simplified View'!D2:D143="Licensing")*(UPPER(TRIM('Fake Simplified View'!C2:C143))="Y"),""),_xlpm.committed6,_xlfn.HSTACK(_xlpm.committed,_xlfn.MAKEARRAY(ROWS(_xlpm.committed),1,_xlfn.LAMBDA(_xlpm.r,_xlpm.c,""))),_xlpm.raw,_xlfn._xlws.FILTER(_xlfn.CHOOSECOLS('Fake Simplified View'!A2:H143,1,2,5,6,7,8),('Fake Simplified View'!D2:D143="Licensing")*(UPPER(TRIM('Fake Simplified View'!C2:C143))<>"Y")),_xlpm.dates,_xlfn.CHOOSECOLS(_xlpm.raw,3),_xlpm.licensing,_xlfn.HSTACK(_xlfn.CHOOSECOLS(_xlpm.raw,1,2),IF(ISNUMBER(_xlpm.dates),IF(_xlpm.dates=0,"",TEXT(_xlpm.dates,"dd-mmm-yy")),_xlpm.dates),_xlfn.CHOOSECOLS(_xlpm.raw,4,5,6)),_xlpm.sortedLicensing,_xlfn.SORTBY(_xlpm.licensing,IF(ISNUMBER(_xlpm.dates),IF(_xlpm.dates>0,_xlpm.dates,1E+99),1E+99),1),_xlfn.VSTACK({"Vendor","Contract","V1 budget","Renewal price","Costout",""},_xlpm.committed6,{"","","","","",""},{"","","","","",""},{"Upcoming licensing vendors","","","","",""},{"Vendor","Contract","Contract date","V1 budget","Renewal price","Costout"},_xlpm.sortedLicensing))} -> Vendor | B31: Contract | C31: V1 budget | D31: Renewal price | E31: Costout | G31: {=_xlfn.LET(_xlpm.cm,('Fake Simplified View'!D2:D143="Licensing")*(UPPER(TRIM('Fake Simplified View'!C2:C143))="Y"),_xlpm.lm,('Fake Simplified View'!D2:D143="Licensing")*(UPPER(TRIM('Fake Simplified View'!C2:C143))<>"Y"),_xlpm.cc,SUM(--_xlpm.cm),_xlpm.lc,SUM(--_xlpm.lm),_xlfn.VSTACK(_xlfn.HSTACK("Committed summary","V1 budget","Renewal price","Costout"),_xlfn.HSTACK(_xlpm.cc&" committed items",SUM(_xlfn._xlws.FILTER('Fake Simplified View'!F2:F143,_xlpm.cm,0)),SUM(_xlfn._xlws.FILTER('Fake Simplified View'!G2:G143,_xlpm.cm,0)),SUM(_xlfn._xlws.FILTER('Fake Simplified View'!H2:H143,_xlpm.cm,0))),_xlfn.MAKEARRAY(_xlpm.cc+2,4,_xlfn.LAMBDA(_xlpm.r,_xlpm.c,"")),_xlfn.HSTACK("Licensing summary","V1 budget","Renewal price","Costout"),_xlfn.HSTACK(_xlpm.lc&" uncommitted items",SUM(_xlfn._xlws.FILTER('Fake Simplified View'!F2:F143,_xlpm.lm,0)),SUM(_xlfn._xlws.FILTER('Fake Simplified View'!G2:G143,_xlpm.lm,0)),SUM(_xlfn._xlws.FILTER('Fake Simplified View'!H2:H143,_xlpm.lm,0)))))} -> Committed summary | H31: V1 budget | I31: Renewal price | J31: Costout
A32: Example Vendor 001 | B32: Example Contract 001 | C32: 31644 | D32: 0 | E32: 31644 | G32: 12 committed items | H32: 342506.41 | I32: 21523 | J32: 320983.41
A33: Example Vendor 002 | B33: Example Contract 002 | C33: 33330.362 | D33: 0 | E33: 33330.362
A34: Example Vendor 003 | B34: Example Contract 003 | C34: 13440 | D34: 0 | E34: 13440
A35: Example Vendor 004 | B35: Example Contract 004 | C35: 588 | D35: 0 | E35: 588
A36: Example Vendor 006 | B36: Example Contract 006 | C36: 187065.6 | D36: 0 | E36: 187065.6
A37: Example Vendor 007 | B37: Example Contract 007 | C37: 5000 | D37: 0 | E37: 5000
A38: Example Vendor 008 | B38: Example Contract 008 | C38: 2.8456501 | D38: 0 | E38: 2.8456501
A39: Example Vendor 009 | B39: Example Contract 009 | C39: 44383.56 | D39: 21315 | E39: 23068.56
A40: Example Vendor 010 | B40: Example Contract 010 | C40: 4748.9171 | D40: 0 | E40: 4748.9171
A41: Example Vendor 027 | B41: Example Contract 038 | C41: 300.42 | D41: 208 | E41: 92.42
A42: Example Vendor 036 | B42: Example Contract 039 | C42: 12400.71 | D42: 0 | E42: 12400.71
A43: Example Vendor 032 | B43: Example Contract 042 | C43: 9602 | D43: 0 | E43: 9602
A46: Upcoming licensing vendors
A47: Vendor | B47: Contract | C47: Contract date | D47: V1 budget | E47: Renewal price | F47: Costout | G47: Licensing summary | H47: V1 budget | I47: Renewal price | J47: Costout
A48: Example Vendor 011 | B48: Example Contract 011 | C48: 31-Jul-26 | D48: 16835.05 | E48: 0 | F48: 16835.05 | G48: 95 uncommitted items | H48: 15231539 | I48: 14823392 | J48: 407591.21
A49: Example Vendor 014 | B49: Example Contract 014 | C49: 31-Jul-26 | D49: 18158.9 | E49: 13921 | F49: 4237.9
A50: Example Vendor 015 | B50: Example Contract 015 | C50: 06-Aug-26 | D50: 10897.62 | E50: 10897.62 | F50: 0
A51: Example Vendor 016 | B51: Example Contract 016 | C51: 07-Aug-26 | D51: 354869.79 | E51: 166469 | F51: 188400.79
...

Sheet Snapshot Wk 1
A1: IT Simplification — FY27 Cost-out Dashboard
A2: Actual savings achieved, remaining opportunity and timing by quarter
A4: V1 BUDGET | D4: ENTERED RENEWAL PRICE | G4: NET IDENTIFIED COSTOUT | I4: FINALISED POSITIVE COSTOUT
A5: 23692506 | D5: 22962976 | G5: 728974.63 | I5: 320983.41
A7: The tracked V1 budget is $23,692,506 and entered renewal prices total $22,962,976. The signed net identified costout in Column J is $728,975. Of the $1,009,252 gross positive costout identified, $320,983 is finalised (31.8%); $280,277 is separately classified as budget variance / reclassification.
A10: QUARTERLY BUDGET, RENEWAL AND COSTOUT OUTLOOK
A11: Metric | B11: Q1 FY27 | C11: Q2 FY27 | D11: Q3 FY27 | E11: Q4 FY27 | F11: Unscheduled | G11: FY27 Total
A12: V1 budget | B12: 844008.17 | C12: 3477136.3 | D12: 1175842.5 | E12: 1272025.9 | F12: 16923494 | G12: 23692506
A13: Entered renewal price | B13: 588167.13 | C13: 3379516.7 | D13: 1172578.4 | E13: 1264749.7 | F13: 16557964 | G13: 22962976
A14: Net identified costout | B14: 255841.04 | C14: 97619.637 | D14: 2708.36 | E14: 7276.18 | F14: 365529.41 | G14: 728974.63
A15: Finalised positive costout | B15: 27820.323 | C15: 22095.13 | D15: 0 | E15: 0 | F15: 271067.96 | G15: 320983.41
A16: Unfinalised positive costout | B16: 230609.96 | C16: 111226.91 | D16: 3088.36 | E16: 48881.52 | F16: 294461.45 | G16: 688268.2
A17: Budget variance / reclassification | B17: 2589.24 | C17: 35702.4 | D17: 380 | E17: 41605.34 | F17: 200000.01 | G17: 280276.99
A19: CATEGORY BUDGET, RENEWAL AND COSTOUT OUTLOOK
A20: Category | B20: V1 budget | C20: Entered renewal price | D20: Net identified costout | E20: Finalised positive costout | F20: Unfinalised positive costout | G20: Budget variance / reclassification
A21: Licensing | B21: 15574045 | C21: 14844915 | D21: 728574.63 | E21: 320983.41 | F21: 687868.2 | G21: 280276.99 | I21: Net identified costout: Overall expected reduction based on all values currently entered
A22: Consumption | B22: 7659712.8 | C22: 7659312.8 | D22: 400.00259 | E22: 0 | F22: 400.00259 | G22: 0 | I22: Finalised positive costout: Savings confirmed/completed
A23: New Spend | B23: 458748.67 | C23: 458748.67 | D23: 0 | E23: 0 | F23: 0 | G23: 0 | I23: Unfinalised positive costout: Savings pipeline - not guaranteed savings
A24: Total | B24: 23692506 | C24: 22962976 | D24: 728974.63 | E24: 320983.41 | F24: 688268.2 | G24: 280276.99
A26: Definitions: Net identified costout = the signed total of Column J across Licensing, Consumption, New Spend and Microsoft. Gross positive costout = positive Column J only. Finalised positive costout = positive Column J where Finalised? is Y. Budget variance / reclassification = the absolute value of negative Column J. Entered renewal price sums values currently populated in Column I. Data note: 8 tracked renewal-price cells are blank, covering $91,963 of V1 budget.
A30: Licensing cost-out to date
A31: Vendor | B31: Contract | C31: V1 budget | D31: Renewal price | E31: Costout | G31: Committed summary | H31: V1 budget | I31: Renewal price | J31: Costout
A32: Example Vendor 001 | B32: Example Contract 001 | C32: 31644 | D32: 0 | E32: 31644 | G32: 12 committed items | H32: 342506.41 | I32: 21523 | J32: 320983.41
A33: Example Vendor 002 | B33: Example Contract 002 | C33: 33330.362 | D33: 0 | E33: 33330.362
A34: Example Vendor 003 | B34: Example Contract 003 | C34: 13440 | D34: 0 | E34: 13440
A35: Example Vendor 004 | B35: Example Contract 004 | C35: 588 | D35: 0 | E35: 588
A36: Example Vendor 006 | B36: Example Contract 006 | C36: 187065.6 | D36: 0 | E36: 187065.6
A37: Example Vendor 007 | B37: Example Contract 007 | C37: 5000 | D37: 0 | E37: 5000
A38: Example Vendor 008 | B38: Example Contract 008 | C38: 2.8456501 | D38: 0 | E38: 2.8456501
A39: Example Vendor 009 | B39: Example Contract 009 | C39: 44383.56 | D39: 21315 | E39: 23068.56
A40: Example Vendor 010 | B40: Example Contract 010 | C40: 4748.9171 | D40: 0 | E40: 4748.9171
A41: Example Vendor 027 | B41: Example Contract 038 | C41: 300.42 | D41: 208 | E41: 92.42
A42: Example Vendor 036 | B42: Example Contract 039 | C42: 12400.71 | D42: 0 | E42: 12400.71
A43: Example Vendor 032 | B43: Example Contract 042 | C43: 9602 | D43: 0 | E43: 9602
A46: Upcoming licensing vendors
A47: Vendor | B47: Contract | C47: Contract date | D47: V1 budget | E47: Renewal price | F47: Costout | G47: Licensing summary | H47: V1 budget | I47: Renewal price | J47: Costout
A48: Example Vendor 011 | B48: Example Contract 011 | C48: 31-Jul-26 | D48: 16835.05 | E48: 0 | F48: 16835.05 | G48: 95 uncommitted items | H48: 15231539 | I48: 14823392 | J48: 407591.21
A49: Example Vendor 014 | B49: Example Contract 014 | C49: 31-Jul-26 | D49: 18158.9 | E49: 13921 | F49: 4237.9
A50: Example Vendor 015 | B50: Example Contract 015 | C50: 06-Aug-26 | D50: 10897.62 | E50: 10897.62 | F50: 0
A51: Example Vendor 016 | B51: Example Contract 016 | C51: 07-Aug-26 | D51: 354869.79 | E51: 166469 | F51: 188400.79
...

Sheet Snapshot Wk 2
A1: IT Simplification — FY27 Cost-out Dashboard
A2: Actual savings achieved, remaining opportunity and timing by quarter
A4: V1 BUDGET | D4: ENTERED RENEWAL PRICE | G4: NET IDENTIFIED COSTOUT | I4: FINALISED POSITIVE COSTOUT
A5: 23692506 | D5: 22938226 | G5: 753724.72 | I5: 556024.67
A7: The tracked V1 budget is $23,692,506 and entered renewal prices total $22,938,226. The signed net identified costout in Column J is $753,725. Of the $1,028,442 gross positive costout identified, $556,025 is finalised (54.1%); $274,717 is separately classified as budget variance / reclassification.
A10: QUARTERLY BUDGET, RENEWAL AND COSTOUT OUTLOOK
A11: Metric | B11: Q1 FY27 | C11: Q2 FY27 | D11: Q3 FY27 | E11: Q4 FY27 | F11: Unscheduled | G11: FY27 Total
A12: V1 budget | B12: 844008.17 | C12: 3477136.3 | D12: 1175842.5 | E12: 1272025.9 | F12: 16923494 | G12: 23692506
A13: Entered renewal price | B13: 571403.04 | C13: 3372027.7 | D13: 1172578.4 | E13: 1264749.7 | F13: 16557467 | G13: 22938226
A14: Net identified costout | B14: 272605.13 | C14: 105108.64 | D14: 2708.36 | E14: 7276.18 | F14: 366026.41 | G14: 753724.72
A15: Finalised positive costout | B15: 254862.68 | C15: 30094.03 | D15: 0 | E15: 0 | F15: 271067.96 | G15: 556024.67
A16: Unfinalised positive costout | B16: 20331.69 | C16: 105157.01 | D16: 3088.36 | E16: 48881.52 | F16: 294958.45 | G16: 472417.03
A17: Budget variance / reclassification | B17: 2589.24 | C17: 30142.4 | D17: 380 | E17: 41605.34 | F17: 200000.01 | G17: 274716.99
A19: CATEGORY BUDGET, RENEWAL AND COSTOUT OUTLOOK
A20: Category | B20: V1 budget | C20: Entered renewal price | D20: Net identified costout | E20: Finalised positive costout | F20: Unfinalised positive costout | G20: Budget variance / reclassification
A21: Licensing | B21: 15574045 | C21: 14820661 | D21: 752827.72 | E21: 556024.67 | F21: 471520.03 | G21: 274716.99 | I21: Net identified costout: Overall expected reduction based on all values currently entered
A22: Consumption | B22: 7659712.8 | C22: 7658815.8 | D22: 897.00259 | E22: 0 | F22: 897.00259 | G22: 0 | I22: Finalised positive costout: Savings confirmed/completed
A23: New Spend | B23: 458748.67 | C23: 458748.67 | D23: 0 | E23: 0 | F23: 0 | G23: 0 | I23: Unfinalised positive costout: Savings pipeline - not guaranteed savings
A24: Total | B24: 23692506 | C24: 22938226 | D24: 753724.72 | E24: 556024.67 | F24: 472417.03 | G24: 274716.99
A26: Definitions: Net identified costout = the signed total of Column J across Licensing, Consumption, New Spend and Microsoft. Gross positive costout = positive Column J only. Finalised positive costout = positive Column J where Finalised? is Y. Budget variance / reclassification = the absolute value of negative Column J. Entered renewal price sums values currently populated in Column I. Data note: 8 tracked renewal-price cells are blank, covering $91,963 of V1 budget.
A30: Licensing cost-out to date
A31: Vendor | B31: Contract | C31: V1 budget | D31: Renewal price | E31: Costout | G31: Committed summary | H31: V1 budget | I31: Renewal price | J31: Costout
A32: Example Vendor 001 | B32: Example Contract 001 | C32: 31644 | D32: 0 | E32: 31644 | G32: 22 committed items | H32: 1053476.8 | I32: 497452.12 | J32: 556024.67
A33: Example Vendor 002 | B33: Example Contract 002 | C33: 33330.362 | D33: 0 | E33: 33330.362
A34: Example Vendor 003 | B34: Example Contract 003 | C34: 13440 | D34: 0 | E34: 13440
A35: Example Vendor 004 | B35: Example Contract 004 | C35: 588 | D35: 0 | E35: 588
A36: Example Vendor 006 | B36: Example Contract 006 | C36: 187065.6 | D36: 0 | E36: 187065.6
A37: Example Vendor 007 | B37: Example Contract 007 | C37: 5000 | D37: 0 | E37: 5000
A38: Example Vendor 008 | B38: Example Contract 008 | C38: 2.8456501 | D38: 0 | E38: 2.8456501
A39: Example Vendor 009 | B39: Example Contract 009 | C39: 44383.56 | D39: 21315 | E39: 23068.56
A40: Example Vendor 010 | B40: Example Contract 010 | C40: 4748.9171 | D40: 0 | E40: 4748.9171
A41: Example Vendor 011 | B41: Example Contract 011 | C41: 16835.05 | D41: 0 | E41: 16835.05
A42: Example Vendor 014 | B42: Example Contract 014 | C42: 18158.9 | D42: 13921 | E42: 4237.9
A43: Example Vendor 016 | B43: Example Contract 016 | C43: 354869.79 | D43: 166469 | E43: 188400.79
A44: Example Vendor 017 | B44: Example Contract 017 | C44: 145598 | D44: 141000 | E44: 4598
... A53: Example Vendor 032 | B53: Example Contract 042 | C53: 9602 | D53: 0 | E53: 9602
A56: Upcoming licensing vendors
A57: Vendor | B57: Contract | C57: Contract date | D57: V1 budget | E57: Renewal price | F57: Costout | G57: Licensing summary | H57: V1 budget | I57: Renewal price | J57: Costout
A58: Example Vendor 015 | B58: Example Contract 015 | C58: 06-Aug-26 | D58: 10897.62 | E58: 10897.62 | F58: 0 | G58: 85 uncommitted items | H58: 14520568 | I58: 14323209 | J58: 196803.04
A59: Example Vendor 025 | B59: Example Contract 025 | C59: 08-Sep-26 | D59: 6959.34 | E59: 6959.34 | F59: 0
...

Sheet Fake Simplified View
A1: Vendor | B1: Contract | C1: Finalised? | D1: Category | E1: When contract is up | F1: V1 budget | G1: Renewal price | H1: Costout | I1: Status
A2: Example Vendor 001 | B2: Example Contract 001 | C2: Y | D2: Licensing | E2: 46203 | F2: 31644 | G2: 0 | H2: =F2-G2 -> 31644
A3: Example Vendor 002 | B3: Example Contract 002 | C3: Y | D3: Licensing | E3: 46203 | F3: 33330.362 | G3: 0 | H3: =F3-G3 -> 33330.362
A4: Example Vendor 003 | B4: Example Contract 003 | C4: Y | D4: Licensing | E4: 46203 | F4: 13440 | G4: 0 | H4: =F4-G4 -> 13440
A5: Example Vendor 004 | B5: Example Contract 004 | C5: Y | D5: Licensing | E5: 46203 | F5: 588 | G5: 0 | H5: =F5-G5 -> 588
A6: Example Vendor 005 | B6: Example Contract 005 | D6: Consumption | E6: NA | F6: 5687336 | G6: 5687336 | H6: =F6-G6 -> 0
A7: Example Vendor 006 | B7: Example Contract 006 | C7: Y | D7: Licensing | E7: 46203 | F7: 187065.6 | G7: 0 | H7: =F7-G7 -> 187065.6
A8: Example Vendor 007 | B8: Example Contract 007 | C8: Y | D8: Licensing | E8: 46203 | F8: 5000 | G8: 0 | H8: =F8-G8 -> 5000
A9: Example Vendor 008 | B9: Example Contract 008 | C9: Y | D9: Licensing | E9: 46206 | F9: 2.8456501 | G9: 0 | H9: =F9-G9 -> 2.8456501
A10: Example Vendor 009 | B10: Example Contract 009 | C10: Y | D10: Licensing | E10: 46223 | F10: 44383.56 | G10: 21315 | H10: =F10-G10 -> 23068.56 | I10: Example status update
A11: Example Vendor 010 | B11: Example Contract 010 | C11: Y | D11: Licensing | E11: 46230 | F11: 4748.9171 | G11: 0 | H11: =F11-G11 -> 4748.9171
A12: Example Vendor 011 | B12: Example Contract 011 | D12: Licensing | E12: 46234 | F12: 16835.05 | G12: 0 | H12: =F12-G12 -> 16835.05
A13: Example Vendor 012 | B13: Example Contract 012 | D13: Consumption | E13: NA | F13: 302217 | G13: 302217 | H13: =F13-G13 -> 0
A14: Example Vendor 013 | B14: Example Contract 013 | D14: Consumption | E14: NA | F14: 3630 | G14: 3630 | H14: =F14-G14 -> 0
A15: Example Vendor 014 | B15: Example Contract 014 | D15: Licensing | E15: 46234 | F15: 18158.9 | G15: 13921 | H15: =F15-G15 -> 4237.9
A16: Example Vendor 015 | B16: Example Contract 015 | D16: Licensing | E16: 46240 | F16: 10897.62 | G16: 10897.62 | H16: =F16-G16 -> 0
A17: Example Vendor 016 | B17: Example Contract 016 | D17: Licensing | E17: 46241 | F17: 354869.79 | G17: 166469 | H17: =F17-G17 -> 188400.79 | I17: Example status update
A18: Example Vendor 017 | B18: Example Contract 017 | D18: Licensing | E18: 46255 | F18: 145598 | G18: 141000 | H18: =F18-G18 -> 4598 | I18: Example status update
A19: Example Vendor 018 | B19: Example Contract 018 | D19: Consumption | E19: NA | F19: 9600 | G19: 9600 | H19: =F19-G19 -> 0
A20: Example Vendor 019 | B20: Example Contract 019 | D20: Consumption | E20: NA | F20: 15000 | G20: 15000 | H20: =F20-G20 -> 0
A21: Example Vendor 020 | B21: Example Contract 020 | D21: Licensing | E21: 46264 | F21: 89342.25 | G21: 81676 | H21: =F21-G21 -> 7666.25 | I21: Example status update
A22: Example Vendor 021 | B22: Example Contract 021 | D22: Licensing | E22: 46265 | F22: 21602.37 | G22: 16705 | H22: =F22-G22 -> 4897.37 | I22: Example status update
A23: Example Vendor 022 | B23: Example Contract 022 | D23: Consumption | E23: NA | F23: 31886.843 | G23: 31886.84 | H23: =F23-G23 -> 0.0025893751
A24: Example Vendor 023 | B24: Example Contract 023 | D24: Consumption | E24: NA | F24: 497 | G24: 497 | H24: =F24-G24 -> 0
A25: Example Vendor 024 | B25: Example Contract 024 | D25: Consumption | E25: NA | F25: 0 | H25: =F25-G25 -> 0
A26: Example Vendor 025 | B26: Example Contract 025 | D26: Licensing | E26: 46273 | F26: 6959.34 | G26: 6959.34 | H26: =F26-G26 -> 0 | I26: Example status update
A27: Example Vendor 026 | B27: Example Contract 026 | D27: Licensing | E27: 46276 | F27: 4000 | G27: 3928.96 | H27: =F27-G27 -> 71.04 | I27: Example status update
A28: Example Vendor 027 | B28: Example Contract 027 | D28: Licensing | E28: 46277 | F28: 3496.56 | G28: 0 | H28: =F28-G28 -> 3496.56 | I28: Example status update
A29: Example Vendor 027 | B29: Example Contract 028 | D29: Licensing | E29: 46277 | F29: 16764.09 | G29: 16764.09 | H29: =F29-G29 -> 0 | I29: Example status update
A30: Example Vendor 028 | B30: Example Contract 029 | D30: Consumption | E30: NA | F30: 973271.2 | G30: 973271.2 | H30: =F30-G30 -> 0
A31: Example Vendor 027 | B31: Example Contract 030 | D31: Licensing | E31: 46277 | F31: 20822.12 | G31: 20822.12 | H31: =F31-G31 -> 0 | I31: Example status update
A32: Example Vendor 029 | B32: Example Contract 031 | D32: Licensing | E32: 46295 | F32: 2116 | G32: 1709 | H32: =F32-G32 -> 407 | I32: Example status update
A33: Example Vendor 030 | B33: Example Contract 032 | D33: New spend | F33: 100000 | G33: 100000 | H33: =F33-G33 -> 0
A34: Example Vendor 031 | B34: Example Contract 033 | D34: Licensing | E34: 46295 | F34: 83410.76 | G34: 86000 | H34: =F34-G34 -> -2589.24 | I34: Example status update
A35: Example Vendor 032 | B35: Example Contract 034 | D35: Licensing | E35: 46297 | F35: 29440 | G35: 35000 | H35: =F35-G35 -> -5560
A36: Example Vendor 033 | B36: Example Contract 035 | D36: Licensing | E36: 46298 | F36: 1771.24 | G36: 1771.24 | H36: =F36-G36 -> 0
A37: Example Vendor 034 | B37: Example Contract 036 | D37: Licensing | E37: 46301 | F37: 12185.9 | G37: 6116 | H37: =F37-G37 -> 6069.9
A38: Example Vendor 035 | B38: Example Contract 037 | D38: Licensing | E38: 46304 | F38: 2558.56 | G38: 2558.56 | H38: =F38-G38 -> 0
A39: Example Vendor 027 | B39: Example Contract 038 | C39: Y | D39: Licensing | E39: 46306 | F39: 300.42 | G39: 208 | H39: =F39-G39 -> 92.42
A40: Example Vendor 036 | B40: Example Contract 039 | C40: Y | D40: Licensing | E40: 46319 | F40: 12400.71 | G40: 0 | H40: =F40-G40 -> 12400.71
...

Sheet Summary JT
B1: V1 Budget | C1: V2 Adjustment | D1: V3 Adjustment | E1: Adjusted Budget | F1: Saving From V1 | H1: Sheet | I1: Vendor | J1: Category | K1: 46204 | L1: 46235 | M1: 46266 | N1: 46296 | O1: 46327 | P1: 46357 | Q1: 46388 | R1: 46419 | S1: 46447 | T1: 46478 | U1: 46508 | V1: 46539 | W1: Q1F27 | X1: Q2F27 | Y1: Q3F27 | Z1: Q4F27 | AA1: FY27 Total
A2: Vendor Spend | H2: Consumption | I2: AWS | J2: Usage Optimisation | K2: 606800 | L2: 0 | M2: 0 | N2: 0 | O2: 0 | P2: 0 | Q2: 0 | R2: 0 | S2: 0 | T2: 0 | U2: 0 | V2: 0 | W2: =SUM(K2:M2) -> 606800 | X2: =SUM(N2:P2) -> 0 | Y2: =SUM(Q2:S2) -> 0 | Z2: =SUM(T2:V2) -> 0 | AA2: =SUM(W2:Z2) -> 606800 | AC2: Notes:
A3: FY27 Addressable | B3: =SUM(#REF!) -> #REF! | C3: =SUM(#REF!) -> #REF! | D3: =SUM(#REF!) -> #REF! | E3: =B3+C3+D3 -> #REF! | F3: =B3-E3 -> #REF! | H3: Consumption | I3: LiveAgent | J3: Product rationalisation | K3: 20620.8 | L3: 0 | M3: 0 | N3: 0 | O3: 0 | P3: 0 | Q3: 0 | R3: 0 | S3: 0 | T3: 0 | U3: 0 | V3: 0 | W3: =SUM(K3:M3) -> 20620.8 | X3: =SUM(N3:P3) -> 0 | Y3: =SUM(Q3:S3) -> 0 | Z3: =SUM(T3:V3) -> 0 | AA3: =W3+X3+Y3+Z3 -> 20620.8 | AC3: For contract renewals, FY27 savings are placed in the month of renewal.
A4: Consumption | B4: =SUM(#REF!) -> #REF! | C4: =SUM(#REF!) -> #REF! | D4: =SUM(#REF!) -> #REF! | E4: =B4+C4+D4 -> #REF! | F4: =B4-E4 -> #REF! | H4: Fusion Related | I4: Oracle Corporation Australia Pty Limited | J4: Product rationalisation | K4: 24798 | L4: 0 | M4: 0 | N4: 0 | O4: 0 | P4: 0 | Q4: 0 | R4: 0 | S4: 0 | T4: 0 | U4: 0 | V4: 0 | W4: =SUM(K4:M4) -> 24798 | X4: =SUM(N4:P4) -> 0 | Y4: =SUM(Q4:S4) -> 0 | Z4: =SUM(T4:V4) -> 0 | AA4: =W4+X4+Y4+Z4 -> 24798 | AC4: For items budgeted for but already exited, FY27 savings placed in July.
A5: Post FY 27 | B5: =SUM(#REF!) -> #REF! | C5: =SUM(#REF!) -> #REF! | D5: =SUM(#REF!) -> #REF! | E5: =B5+C5+D5 -> #REF! | F5: =B5-E5 -> #REF! | H5: FY27 Addressable | I5: Adobe Systems Software Ireland Limited | J5: License Optimisation | K5: 0 | L5: 0 | M5: 0 | N5: 0 | O5: 0 | P5: 0 | Q5: 415000 | R5: 0 | S5: 0 | T5: 0 | U5: 0 | V5: 0 | W5: =SUM(K5:M5) -> 0 | X5: =SUM(N5:P5) -> 0 | Y5: =SUM(Q5:S5) -> 415000 | Z5: =SUM(T5:V5) -> 0 | AA5: =W5+X5+Y5+Z5 -> 415000 | AC5: For items budgeted for but already decided against, FY27 savings placed in July.
A6: New Spend | B6: =SUM(#REF!) -> #REF! | C6: =SUM(#REF!) -> #REF! | D6: =SUM(#REF!) -> #REF! | E6: =B6+C6+D6 -> #REF! | F6: =B6-E6 -> #REF! | H6: FY27 Addressable | I6: AWS Marketplace - Splunk | J6: License Optimisation | K6: 0 | L6: 0 | M6: 0 | N6: 0 | O6: 0 | P6: 0 | Q6: 75000 | R6: 0 | S6: 0 | T6: 0 | U6: 0 | V6: 0 | W6: =SUM(K6:M6) -> 0 | X6: =SUM(N6:P6) -> 0 | Y6: =SUM(Q6:S6) -> 75000 | Z6: =SUM(T6:V6) -> 0 | AA6: =W6+X6+Y6+Z6 -> 75000 | AC6: For items where we bugeted to increase licenses, but have now decided to remain at FY26 levels, FY27 savings placed in July.
A7: Microsoft Related | B7: =SUM(#REF!) -> #REF! | C7: =SUM(#REF!) -> #REF! | D7: =SUM(#REF!) -> #REF! | E7: =B7+C7+D7 -> #REF! | F7: =B7-E7 -> #REF! | H7: FY27 Addressable | I7: China Telecom | J7: Transformation Activities | K7: 31644 | L7: 0 | M7: 0 | N7: 0 | O7: 0 | P7: 0 | Q7: 0 | R7: 0 | S7: 0 | T7: 0 | U7: 0 | V7: 0 | W7: =SUM(K7:M7) -> 31644 | X7: =SUM(N7:P7) -> 0 | Y7: =SUM(Q7:S7) -> 0 | Z7: =SUM(T7:V7) -> 0 | AA7: =W7+X7+Y7+Z7 -> 31644 | AC7: Consumption savings for FY27 placed in July.
A8: Total Vendor Spend: | B8: =SUM(B3:B7) -> #REF! | C8: =SUM(C3:C7) -> #REF! | D8: =SUM(D3:D7) -> #REF! | E8: =SUM(E3:E7) -> #REF! | F8: =SUM(F3:F7) -> #REF! | H8: FY27 Addressable | I8: ContactMonkey | J8: License Optimisation | K8: 0 | L8: 20000 | M8: 0 | N8: 0 | O8: 0 | P8: 0 | Q8: 0 | R8: 0 | S8: 0 | T8: 0 | U8: 0 | V8: 0 | W8: =SUM(K8:M8) -> 20000 | X8: =SUM(N8:P8) -> 0 | Y8: =SUM(Q8:S8) -> 0 | Z8: =SUM(T8:V8) -> 0 | AA8: =W8+X8+Y8+Z8 -> 20000 | AC8: I'm not 100% convinced about LiveAgent as, from the last emails I saw, it was on the list to sunset but not immediately.
H9: FY27 Addressable | I9: Digital Mass | J9: Product rationalisation | K9: 33330.36 | L9: 0 | M9: 0 | N9: 0 | O9: 0 | P9: 0 | Q9: 0 | R9: 0 | S9: 0 | T9: 0 | U9: 0 | V9: 0 | W9: =SUM(K9:M9) -> 33330.36 | X9: =SUM(N9:P9) -> 0 | Y9: =SUM(Q9:S9) -> 0 | Z9: =SUM(T9:V9) -> 0 | AA9: =W9+X9+Y9+Z9 -> 33330.36
A10: Non-Vendor Spend | H10: FY27 Addressable | I10: Dragon Metrics | J10: Product rationalisation | K10: 13440 | L10: 0 | M10: 0 | N10: 0 | O10: 0 | P10: 0 | Q10: 0 | R10: 0 | S10: 0 | T10: 0 | U10: 0 | V10: 0 | W10: =SUM(K10:M10) -> 13440 | X10: =SUM(N10:P10) -> 0 | Y10: =SUM(Q10:S10) -> 0 | Z10: =SUM(T10:V10) -> 0 | AA10: =W10+X10+Y10+Z10 -> 13440
A11: Staff Aug | B11: =SUM(#REF!) -> #REF! | C11: =SUM(#REF!) -> #REF! | D11: =SUM(#REF!) -> #REF! | E11: =B11+C11+D11 -> #REF! | F11: =B11-E11 -> #REF! | H11: FY27 Addressable | I11: Equinix Australia Pty Ltd | J11: Product rationalisation | K11: 0 | L11: 0 | M11: 0 | N11: 0 | O11: 0 | P11: 0 | Q11: 0 | R11: 0 | S11: 0 | T11: 0 | U11: 23871.53 | V11: 0 | W11: =SUM(K11:M11) -> 0 | X11: =SUM(N11:P11) -> 0 | Y11: =SUM(Q11:S11) -> 0 | Z11: =SUM(T11:V11) -> 23871.53 | AA11: =W11+X11+Y11+Z11 -> 23871.53
A12: Professional Consultancy | B12: =SUM(#REF!) -> #REF! | C12: =SUM(#REF!) -> #REF! | D12: =SUM(#REF!) -> #REF! | E12: =B12+C12+D12 -> #REF! | F12: =B12-E12 -> #REF! | H12: FY27 Addressable | I12: Happy Scribe | J12: Product rationalisation | K12: 588 | L12: 0 | M12: 0 | N12: 0 | O12: 0 | P12: 0 | Q12: 0 | R12: 0 | S12: 0 | T12: 0 | U12: 0 | V12: 0 | W12: =SUM(K12:M12) -> 588 | X12: =SUM(N12:P12) -> 0 | Y12: =SUM(Q12:S12) -> 0 | Z12: =SUM(T12:V12) -> 0 | AA12: =W12+X12+Y12+Z12 -> 588
A13: Miscellaneous | B13: =SUM(#REF!) -> #REF! | C13: =SUM(#REF!) -> #REF! | D13: =SUM(#REF!) -> #REF! | E13: =B13+C13+D13 -> #REF! | F13: =B13-E13 -> #REF! | H13: FY27 Addressable | I13: Import.io | J13: License Optimisation | K13: 30000 | L13: 0 | M13: 0 | N13: 0 | O13: 0 | P13: 0 | Q13: 0 | R13: 0 | S13: 0 | T13: 0 | U13: 0 | V13: 0 | W13: =SUM(K13:M13) -> 30000 | X13: =SUM(N13:P13) -> 0 | Y13: =SUM(Q13:S13) -> 0 | Z13: =SUM(T13:V13) -> 0 | AA13: =W13+X13+Y13+Z13 -> 30000
A14: Non-Tech Budget | B14: =SUM(#REF!) -> #REF! | C14: =SUM(#REF!) -> #REF! | D14: =SUM(#REF!) -> #REF! | E14: =B14+C14+D14 -> #REF! | F14: =B14-E14 -> #REF! | H14: FY27 Addressable | I14: Ionic Inc. | J14: License Optimisation | K14: 0 | L14: 0 | M14: 0 | N14: 0 | O14: 0 | P14: 0 | Q14: 11000 | R14: 0 | S14: 0 | T14: 0 | U14: 0 | V14: 0 | W14: =SUM(K14:M14) -> 0 | X14: =SUM(N14:P14) -> 0 | Y14: =SUM(Q14:S14) -> 11000 | Z14: =SUM(T14:V14) -> 0 | AA14: =W14+X14+Y14+Z14 -> 11000
A15: Total Non-Vendor Spend: | B15: =SUM(B11:B14) -> #REF! | C15: =SUM(C11:C14) -> #REF! | D15: =SUM(D11:D14) -> #REF! | E15: =SUM(E11:E14) -> #REF! | F15: =SUM(F11:F14) -> #REF! | H15: FY27 Addressable | I15: LinkedIn Singapore Pte Ltd | J15: License Optimisation | K15: 0 | L15: 195657 | M15: 0 | N15: 0 | O15: 0 | P15: 0 | Q15: 0 | R15: 0 | S15: 0 | T15: 0 | U15: 0 | V15: 0 | W15: =SUM(K15:M15) -> 195657 | X15: =SUM(N15:P15) -> 0 | Y15: =SUM(Q15:S15) -> 0 | Z15: =SUM(T15:V15) -> 0 | AA15: =W15+X15+Y15+Z15 -> 195657
H16: FY27 Addressable | I16: Lucid Software Inc. | J16: License Optimisation | K16: 30000 | L16: 0 | M16: 0 | N16: 0 | O16: 0 | P16: 0 | Q16: 0 | R16: 0 | S16: 0 | T16: 0 | U16: 0 | V16: 0 | W16: =SUM(K16:M16) -> 30000 | X16: =SUM(N16:P16) -> 0 | Y16: =SUM(Q16:S16) -> 0 | Z16: =SUM(T16:V16) -> 0 | AA16: =W16+X16+Y16+Z16 -> 30000
H17: FY27 Addressable | I17: UXCam Inc. | J17: License Optimisation | K17: 13000 | L17: 0 | M17: 0 | N17: 0 | O17: 0 | P17: 0 | Q17: 0 | R17: 0 | S17: 0 | T17: 0 | U17: 0 | V17: 0 | W17: =SUM(K17:M17) -> 13000 | X17: =SUM(N17:P17) -> 0 | Y17: =SUM(Q17:S17) -> 0 | Z17: =SUM(T17:V17) -> 0 | AA17: =W17+X17+Y17+Z17 -> 13000
A18: Fusion Related | B18: =SUM(#REF!) -> #REF! | C18: =SUM(#REF!) -> #REF! | D18: =SUM(#REF!) -> #REF! | E18: =B18+C18+D18 -> #REF! | F18: =B18-E18 -> #REF! | H18: FY27 Addressable | I18: Voucherify P.S.A | J18: License Optimisation | K18: 0 | L18: 0 | M18: 0 | N18: 0 | O18: 0 | P18: 7000 | Q18: 0 | R18: 0 | S18: 0 | T18: 0 | U18: 0 | V18: 0 | W18: =SUM(K18:M18) -> 0 | X18: =SUM(N18:P18) -> 7000 | Y18: =SUM(Q18:S18) -> 0 | Z18: =SUM(T18:V18) -> 0 | AA18: =W18+X18+Y18+Z18 -> 7000
H19: FY27 Addressable | I19: Walkme | J19: Product rationalisation | K19: 187066 | L19: 0 | M19: 0 | N19: 0 | O19: 0 | P19: 0 | Q19: 0 | R19: 0 | S19: 0 | T19: 0 | U19: 0 | V19: 0 | W19: =SUM(K19:M19) -> 187066 | X19: =SUM(N19:P19) -> 0 | Y19: =SUM(Q19:S19) -> 0 | Z19: =SUM(T19:V19) -> 0 | AA19: =W19+X19+Y19+Z19 -> 187066
A20: Total Vendor Spend: | B20: =B18+B15+B8 -> #REF! | C20: =C18+C15+C8 -> #REF! | D20: =D18+D15+D8 -> #REF! | E20: =E18+E15+E8 -> #REF! | F20: =F18+F15+F8 -> #REF! | H20: FY27 Addressable | I20: Zoom Video Communications Inc | J20: License Optimisation | K20: 0 | L20: 0 | M20: 0 | N20: 0 | O20: 0 | P20: 0 | Q20: 0 | R20: 0 | S20: 0 | T20: 0 | U20: 0 | V20: 23000 | W20: =SUM(K20:M20) -> 0 | X20: =SUM(N20:P20) -> 0 | Y20: =SUM(Q20:S20) -> 0 | Z20: =SUM(T20:V20) -> 23000 | AA20: =W20+X20+Y20+Z20 -> 23000
H21: Microsoft Related | I21: Microsoft | J21: License Optimisation | K21: 0 | L21: 0 | M21: 0 | N21: 1999808.8 | O21: 0 | P21: 0 | Q21: 0 | R21: 0 | S21: 0 | T21: 0 | U21: 0 | V21: 0 | W21: =SUM(K21:M21) -> 0 | X21: =SUM(N21:P21) -> 1999808.8 | Y21: =SUM(Q21:S21) -> 0 | Z21: =SUM(T21:V21) -> 0 | AA21: =W21+X21+Y21+Z21 -> 1999808.8
A22: Jessy File: | B22: 42325358 | H22: New Spend | I22: Microsoft Pty Ltd | J22: Product rationalisation | K22: 243750 | L22: 0 | M22: 0 | N22: 0 | O22: 0 | P22: 0 | Q22: 0 | R22: 0 | S22: 0 | T22: 0 | U22: 0 | V22: 0 | W22: =SUM(K22:M22) -> 243750 | X22: =SUM(N22:P22) -> 0 | Y22: =SUM(Q22:S22) -> 0 | Z22: =SUM(T22:V22) -> 0 | AA22: =W22+X22+Y22+Z22 -> 243750
H23: Post FY 27 | I23: AWS Marketplace - GitLab | J23: Capitalisation | K23: 182510 | L23: 0 | M23: 0 | N23: 0 | O23: 0 | P23: 0 | Q23: 0 | R23: 0 | S23: 0 | T23: 0 | U23: 0 | V23: 0 | W23: =SUM(K23:M23) -> 182510 | X23: =SUM(N23:P23) -> 0 | Y23: =SUM(Q23:S23) -> 0 | Z23: =SUM(T23:V23) -> 0 | AA23: =W23+X23+Y23+Z23 -> 182510
A24: Difference: | B24: =B20-B22 -> #REF! | C24: Budget transfer of Dilligent for V1 | H24: Post FY 27 | I24: Snyk Limited | J24: License Optimisation | K24: 93836.8 | L24: 0 | M24: 0 | N24: 0 | O24: 0 | P24: 0 | Q24: 0 | R24: 0 | S24: 0 | T24: 0 | U24: 0 | V24: 0 | W24: =SUM(K24:M24) -> 93836.8 | X24: =SUM(N24:P24) -> 0 | Y24: =SUM(Q24:S24) -> 0 | Z24: =SUM(T24:V24) -> 0 | AA24: =W24+X24+Y24+Z24 -> 93836.8
H25: Professional Consultancy | I25: Mantel Group Pty Ltd | J25: Usage Optimisation | K25: 30000 | L25: 0 | M25: 0 | N25: 0 | O25: 0 | P25: 0 | Q25: 0 | R25: 0 | S25: 0 | T25: 0 | U25: 0 | V25: 0 | W25: =SUM(K25:M25) -> 30000 | X25: =SUM(N25:P25) -> 0 | Y25: =SUM(Q25:S25) -> 0 | Z25: =SUM(T25:V25) -> 0 | AA25: =W25+X25+Y25+Z25 -> 30000
H26: Staff Aug | I26: ConnectOS Pty Ltd | J26: Usage Optimisation | K26: 570000 | L26: 0 | M26: 0 | N26: 0 | O26: 0 | P26: 0 | Q26: 0 | R26: 0 | S26: 0 | T26: 0 | U26: 0 | V26: 0 | W26: =SUM(K26:M26) -> 570000 | X26: =SUM(N26:P26) -> 0 | Y26: =SUM(Q26:S26) -> 0 | Z26: =SUM(T26:V26) -> 0 | AA26: =W26+X26+Y26+Z26 -> 570000
I27: Total Cost Out: | K27: =SUM(K2:K26) -> 2111384 | L27: =SUM(L2:L26) -> 215657 | M27: =SUM(M2:M26) -> 0 | N27: =SUM(N2:N26) -> 1999808.8 | O27: =SUM(O2:O26) -> 0 | P27: =SUM(P2:P26) -> 7000 | Q27: =SUM(Q2:Q26) -> 501000 | R27: =SUM(R2:R26) -> 0 | ... AA27: =SUM(AA2:AA26) -> 4881721.3
I29: Vendor | J29: Category
A30: - | H30: Fusion Related | I30: Rimini Street, Inc | K30: -122582.57 | L30: 0 | M30: 0 | N30: 0 | O30: 0 | P30: 0 | Q30: 0 | R30: 0 | S30: 0 | T30: 0 | U30: 0 | V30: 0 | W30: =SUM(K30:M30) -> -122582.57 | X30: =SUM(N30:P30) -> 0 | Y30: =SUM(Q30:S30) -> 0 | Z30: =SUM(T30:V30) -> 0 | AA30: =W30+X30+Y30+Z30 -> -122582.57
H31: Post FY 27 | I31: Diligent One Platform | K31: -20000 | L31: 0 | M31: 0 | N31: 0 | O31: 0 | P31: 0 | Q31: 0 | R31: 0 | S31: 0 | T31: 0 | U31: 0 | V31: 0 | W31: =SUM(K31:M31) -> -20000 | X31: =SUM(N31:P31) -> 0 | Y31: =SUM(Q31:S31) -> 0 | Z31: =SUM(T31:V31) -> 0 | AA31: =W31+X31+Y31+Z31 -> -20000
H32: Post FY 27 | I32: Gartner Midsize Enterprise | K32: -171000 | L32: 0 | M32: 0 | N32: 0 | O32: 0 | P32: 0 | Q32: 0 | R32: 0 | S32: 0 | T32: 0 | U32: 0 | V32: 0 | W32: =SUM(K32:M32) -> -171000 | X32: =SUM(N32:P32) -> 0 | Y32: =SUM(Q32:S32) -> 0 | Z32: =SUM(T32:V32) -> 0 | AA32: =W32+X32+Y32+Z32 -> -171000
H33: FY27 Addressable | I33: Ahrefs Pte Ltd | K33: -33440 | L33: 0 | M33: 0 | N33: 0 | O33: 0 | P33: 0 | Q33: 0 | R33: 0 | S33: 0 | T33: 0 | U33: 0 | V33: 0 | W33: =SUM(K33:M33) -> -33440 | X33: =SUM(N33:P33) -> 0 | Y33: =SUM(Q33:S33) -> 0 | Z33: =SUM(T33:V33) -> 0 | AA33: =W33+X33+Y33+Z33 -> -33440
I34: Total Cost In: | K34: =SUM(K30:K33) -> -347022.57 | L34: =SUM(L30:L33) -> 0 | M34: =SUM(M30:M33) -> 0 | N34: =SUM(N30:N33) -> 0 | O34: =SUM(O30:O33) -> 0 | P34: =SUM(P30:P33) -> 0 | Q34: =SUM(Q30:Q33) -> 0 | R34: =SUM(R30:R33) -> 0 | ... AA34: =SUM(AA30:AA33) -> -347022.57

Sheet FY27 Budget Template
B1: ***DO NOT SORT THIS PAGE. IT STUFFS THE FORMULAS*** | D1: ALL YELLOW CELLS REQUIRE INPUT | H1: 319 - pure OSM direct cost | J1: =39258-39258 -> 0 | L1: =SUBTOTAL(9,L4:L1001) -> 42325358 | N1: =SUBTOTAL(9,N4:N1001) -> -2741765.8 | O1: =SUBTOTAL(9,O4:O1001) -> -822508 | P1: =SUBTOTAL(9,P4:P1001) -> 38761084
L2: BUDGET | P2: BUDGET
A3: Ref | B3: Vendor | C3: Product | D3: Function | E3: GTLT/Tech Owner/ Business Owner | F3: CC | G3: GL | H3: Type | I3: Start | J3: End | K3: Term (months) | L3: F27B Total | M3: Var F27 v F26 (Fav)/Unfav (v1) | N3: Adjustment V2 | O3: Adjustment V3 | P3: F27B Total V3
A4: 263 | B4: Abebe Tedila Mengistie | D4: Tech | F4: 511HDO | G4: 8700 | H4: Consumption | K4: =IF(OR(I4="",J4=""),"Monthly",IF(J4<I4,0,(YEAR(J4)-YEAR(I4))*12+(MONTH(J4)-MONTH(I4))+1-IF(DAY(J4)<DAY(I4),1,0))) -> Monthly | L4: 20731.599 | M4: 20731.599 | P4: 20731.599
A5: 30 | B5: Adjust GmbH | C5: Adjust Core - 1,000,000 Conversions | D5: Marketing | E5: Neeraja/Amudha | F5: 213BTI | G5: 8200 | H5: Fixed | I5: 45901 | J5: 46265 | K5: =IF(OR(I5="",J5=""),"",IF(J5<I5,0,(YEAR(J5)-YEAR(I5))*12+(MONTH(J5)-MONTH(I5))+1-IF(DAY(J5)<DAY(I5),1,0))) -> 12 | L5: 21602.37 | M5: 5949.4456 | P5: 21602.37
A6: 31 | B6: Adobe Systems Software Ireland Limited | C6: Marketo - Student Placement (Year 1- 1.2M, Year 2- $1.5M, Year 3- $1.7M) | D6: Marketing | E6: Neeraja/ Antony Nelson/Michelle Callanan | F6: 213BTI | G6: 8200 | H6: Fixed | I6: 45292 | J6: 46387 | K6: =IF(OR(I6="",J6=""),"",IF(J6<I6,0,(YEAR(J6)-YEAR(I6))*12+(MONTH(J6)-MONTH(I6))+1-IF(DAY(J6)<DAY(I6),1,0))) -> 36 | L6: 1806000 | M6: 347802.13 | N6: -275000 | P6: 1531000
A7: 32 | B7: Adobe Systems Software Ireland Limited | C7: Marketo Engage - Additional Dynamic Chat seats - 70 | D7: Marketing | E7: Neeraja/ Antony Nelson/Michelle Callanan | F7: 213BTI | G7: 8200 | H7: Fixed | I7: 45505 | J7: 46392 | K7: =IF(OR(I7="",J7=""),"",IF(J7<I7,0,(YEAR(J7)-YEAR(I7))*12+(MONTH(J7)-MONTH(I7))+1-IF(DAY(J7)<DAY(I7),1,0))) -> 30 | L7: 76651.437 | M7: 18278.201 | N7: -10000 | P7: 66651.437
A8: FY27B | B8: Ahrefs, SEMRush | C8: SEO Tools - Regional | D8: Marketing | E8: Michelle C/Joel Knight | F8: 511HDO | G8: 8200 | K8: =IF(OR(I8="",J8=""),"Monthly",IF(J8<I8,0,(YEAR(J8)-YEAR(I8))*12+(MONTH(J8)-MONTH(I8))+1-IF(DAY(J8)<DAY(I8),1,0))) -> Monthly | L8: 20000 | M8: 20000 | O8: 33440 | P8: 53440
A9: 1 | B9: Amazon Web Services Australia Pty Ltd | C9: PPA Commitment | D9: DM | E9: Neeraja / Jayakumar | F9: 794HGB01 | G9: 8200 | H9: Consumption | I9: 45870 | J9: 46965 | K9: =IF(OR(I9="",J9=""),"",IF(J9<I9,0,(YEAR(J9)-YEAR(I9))*12+(MONTH(J9)-MONTH(I9))+1-IF(DAY(J9)<DAY(I9),1,0))) -> 36 | L9: -672153 | M9: -672153 | P9: -672153
A10: 1 | B10: Amazon Web Services Australia Pty Ltd | C10: PPA Commitment | D10: Envoy | E10: Neeraja / Jayakumar | F10: 346 Envoy | G10: 8200 | H10: Consumption | I10: 45870 | J10: 46965 | K10: =IF(OR(I10="",J10=""),"",IF(J10<I10,0,(YEAR(J10)-YEAR(I10))*12+(MONTH(J10)-MONTH(I10))+1-IF(DAY(J10)<DAY(I10),1,0))) -> 36 | L10: -11351 | M10: -11351 | P10: -11351
A11: 1 | B11: Amazon Web Services Australia Pty Ltd | C11: PPA Commitment | D11: Envoy | E11: Neeraja / Jayakumar | F11: 346 Envoy | G11: 8200 | H11: Consumption | I11: 45870 | J11: 46965 | K11: =IF(OR(I11="",J11=""),"",IF(J11<I11,0,(YEAR(J11)-YEAR(I11))*12+(MONTH(J11)-MONTH(I11))+1-IF(DAY(J11)<DAY(I11),1,0))) -> 36 | L11: 11351 | M11: 11351 | P11: 11351
B12: Amazon Web Services Australia Pty Ltd | C12: PPA Commitment | D12: Tech | E12: Neeraja / Jayakumar | F12: 511HDO | G12: 8200 | H12: Consumption | I12: 45870 | J12: 46965 | K12: =IF(OR(I12="",J12=""),"",IF(J12<I12,0,(YEAR(J12)-YEAR(I12))*12+(MONTH(J12)-MONTH(I12))+1-IF(DAY(J12)<DAY(I12),1,0))) -> 36 | L12: 46800 | M12: 46800 | N12: -46800 | P12: 0
A13: 1 | B13: Amazon Web Services Australia Pty Ltd | C13: PPA Commitment | D13: LT | E13: Neeraja / Jayakumar | F13: 319IEO | G13: 8200 | H13: Consumption | I13: 45870 | J13: 46965 | K13: =IF(OR(I13="",J13=""),"",IF(J13<I13,0,(YEAR(J13)-YEAR(I13))*12+(MONTH(J13)-MONTH(I13))+1-IF(DAY(J13)<DAY(I13),1,0))) -> 36 | L13: 273914 | M13: 64420.05 | N13: -30000 | P13: 243914
A14: 1 | B14: Amazon Web Services Australia Pty Ltd | C14: PPA Commitment | D14: Analytics | E14: Neeraja / Jayakumar | F14: 513HDO | G14: 8200 | H14: Consumption | I14: 45870 | J14: 46965 | K14: =IF(OR(I14="",J14=""),"",IF(J14<I14,0,(YEAR(J14)-YEAR(I14))*12+(MONTH(J14)-MONTH(I14))+1-IF(DAY(J14)<DAY(I14),1,0))) -> 36 | L14: 354709 | M14: -18401.51 | N14: -40000 | P14: 314709
A15: 1 | B15: Amazon Web Services Australia Pty Ltd | C15: PPA Commitment | D15: DM | E15: Neeraja / Jayakumar | F15: 794HGB01 | G15: 8200 | H15: Consumption | I15: 45870 | J15: 46965 | K15: =IF(OR(I15="",J15=""),"",IF(J15<I15,0,(YEAR(J15)-YEAR(I15))*12+(MONTH(J15)-MONTH(I15))+1-IF(DAY(J15)<DAY(I15),1,0))) -> 36 | L15: 672153 | M15: 672153 | P15: 672153
A16: 1 | B16: Amazon Web Services Australia Pty Ltd | C16: PPA Commitment | D16: SP | E16: Neeraja / Jayakumar | F16: 213BTI | G16: 8200 | H16: Consumption | I16: 45870 | J16: 46965 | K16: =IF(OR(I16="",J16=""),"",IF(J16<I16,0,(YEAR(J16)-YEAR(I16))*12+(MONTH(J16)-MONTH(I16))+1-IF(DAY(J16)<DAY(I16),1,0))) -> 36 | L16: 1606542 | M16: 221589.11 | N16: -190000 | P16: 1416542
A17: 1 | B17: Amazon Web Services Australia Pty Ltd | C17: PPA Commitment | D17: LT | E17: Neeraja / Jayakumar | F17: 308IEA | G17: 8200 | H17: Consumption | I17: 45870 | J17: 46965 | K17: =IF(OR(I17="",J17=""),"",IF(J17<I17,0,(YEAR(J17)-YEAR(I17))*12+(MONTH(J17)-MONTH(I17))+1-IF(DAY(J17)<DAY(I17),1,0))) -> 36 | L17: 2721867 | M17: 177350.91 | N17: -300000 | P17: 2421867
A18: 34 | B18: APNIC Pty Ltd | C18: Annual Membership, IDP Public IP in Aus | D18: Cyber | E18: Simon Cowley | F18: 514HDO | G18: 8200 | H18: Fixed | I18: 45931 | J18: 46295 | K18: =IF(OR(I18="",J18=""),"",IF(J18<I18,0,(YEAR(J18)-YEAR(I18))*12+(MONTH(J18)-MONTH(I18))+1-IF(DAY(J18)<DAY(I18),1,0))) -> 12 | L18: 2115.839 | M18: -438.80164 | P18: 2115.839
A19: 35 | B19: App Samurai Limited | C19: Storyly | D19: DM | E19: Neeraja / Sasi kumar | F19: 516HDO | G19: 8200 | H19: Fixed | I19: 45870 | J19: 46234 | K19: =IF(OR(I19="",J19=""),"",IF(J19<I19,0,(YEAR(J19)-YEAR(I19))*12+(MONTH(J19)-MONTH(I19))+1-IF(DAY(J19)<DAY(I19),1,0))) -> 12 | L19: 16835.047 | M19: 7813.3442 | P19: 16835.047
A20: 36 | B20: Apple Inc. | C20: DC Apple Developer Account - IDP Connect (Lower enviroment) | D20: DM,LT & SP | E20: Neeraja / Kishore Mohanarangam | F20: 516HDO | G20: 8200 | H20: Fixed | I20: 46046 | J20: 46410 | K20: =IF(OR(I20="",J20=""),"",IF(J20<I20,0,(YEAR(J20)-YEAR(I20))*12+(MONTH(J20)-MONTH(I20))+1-IF(DAY(J20)<DAY(I20),1,0))) -> 12 | L20: 839.9782 | M20: 628.97504 | P20: 839.9782
A21: 2 | B21: Appointlet | D21: SP | E21: Neeraja/Bala | F21: 516HDO | G21: 8200 | H21: Consumption | I21: 46000 | J21: 46364 | K21: =IF(OR(I21="",J21=""),"",IF(J21<I21,0,(YEAR(J21)-YEAR(I21))*12+(MONTH(J21)-MONTH(I21))+1-IF(DAY(J21)<DAY(I21),1,0))) -> 12 | L21: 16000 | M21: 10800 | P21: 16000
A22: 39 | B22: Aussie Broadband Limited | C22: Aussie Broadband - Fibre Links | E22: Lewis Lee | F22: 517HDO | G22: 8800 | H22: Fixed | I22: 45839 | J22: 46934 | K22: =IF(OR(I22="",J22=""),"",IF(J22<I22,0,(YEAR(J22)-YEAR(I22))*12+(MONTH(J22)-MONTH(I22))+1-IF(DAY(J22)<DAY(I22),1,0))) -> 36 | L22: 48151.609 | M22: 4938.9725 | P22: 48151.609
A23: 40 | B23: AwardForce | C23: Awards Management Platform - to Manage Award Programs | D23: Marketing | E23: Michelle Callanan/ Annie Sun | F23: 511HDO | G23: 8200 | H23: Fixed | I23: 45990 | J23: 46354 | K23: =IF(OR(I23="",J23=""),"",IF(J23<I23,0,(YEAR(J23)-YEAR(I23))*12+(MONTH(J23)-MONTH(I23))+1-IF(DAY(J23)<DAY(I23),1,0))) -> 12 | L23: 15442.021 | M23: 2244.8592 | P23: 15442.021
A24: FY27B | B24: AWS Marketplace - Anthropic PBC | C24: Claude | D24: SP | E24: Business Case: C213 AAV | F24: 213BTI | G24: 8200 | H24: Consumption | K24: =IF(OR(I24="",J24=""),"Monthly",IF(J24<I24,0,(YEAR(J24)-YEAR(I24))*12+(MONTH(J24)-MONTH(I24))+1-IF(DAY(J24)<DAY(I24),1,0))) -> Monthly | L24: 102217 | M24: 102217 | P24: 102217
A25: FY27B | B25: AWS Marketplace - Anthropic PBC | C25: Claude | D25: SP | E25: Stuart Nickols Business Case: C205 Navi | F25: 213BTI | G25: 8200 | H25: Consumption | K25: =IF(OR(I25="",J25=""),"Monthly",IF(J25<I25,0,(YEAR(J25)-YEAR(I25))*12+(MONTH(J25)-MONTH(I25))+1-IF(DAY(J25)<DAY(I25),1,0))) -> Monthly | L25: 200000 | M25: 200000 | P25: 200000
A26: 4 | B26: AWS Marketplace - ClamAV | C26: BucketAV Software | D26: Cyber | E26: Simon Cowley | F26: 514HDO | G26: 8200 | H26: Consumption | K26: =IF(OR(I26="",J26=""),"",IF(J26<I26,0,(YEAR(J26)-YEAR(I26))*12+(MONTH(J26)-MONTH(I26))+1-IF(DAY(J26)<DAY(I26),1,0))) | L26: 3630 | M26: 497.15 | P26: 3630
A27: 204 | B27: AWS Marketplace - Cloudec | C27: Managed Services | D27: Cloudops | E27: Lewis Lee | F27: 513HDO | G27: 8700 | H27: Fixed | I27: 46056 | J27: 46144 | K27: =IF(OR(I27="",J27=""),"",IF(J27<I27,0,(YEAR(J27)-YEAR(I27))*12+(MONTH(J27)-MONTH(I27))+1-IF(DAY(J27)<DAY(I27),1,0))) -> 3 | L27: 63000 | M27: 12762.447 | P27: 63000
A28: 208 | B28: AWS Marketplace – Commvault | C28: Commvault Cloud SaaS Jumpstart | D28: Platform & Infrastructure | F28: 513HDO | G28: 8200 | H28: Fixed | I28: 46027 | J28: 47122 | K28: =IF(OR(I28="",J28=""),"",IF(J28<I28,0,(YEAR(J28)-YEAR(I28))*12+(MONTH(J28)-MONTH(I28))+1-IF(DAY(J28)<DAY(I28),1,0))) -> 36 | L28: 286994.42 | M28: 167311.09 | P28: 286994.42
A29: 435 | B29: AWS Marketplace – Commvault | D29: Tech | E29: Neeraja/Jayakumar | F29: 490HDO | G29: 8200 | H29: Other | K29: =IF(OR(I29="",J29=""),"Monthly",IF(J29<I29,0,(YEAR(J29)-YEAR(I29))*12+(MONTH(J29)-MONTH(I29))+1-IF(DAY(J29)<DAY(I29),1,0))) -> Monthly | L29: 268316 | M29: 218372.16 | P29: 268316
A30: FY27B | B30: AWS Marketplace - CyberCX | C30: China licenses Premium (220 @USD50) | D30: Cyber | E30: Simon Cowley | F30: 514HDO | G30: 8200 | H30: Fixed | K30: =IF(OR(I30="",J30=""),"Monthly",IF(J30<I30,0,(YEAR(J30)-YEAR(I30))*12+(MONTH(J30)-MONTH(I30))+1-IF(DAY(J30)<DAY(I30),1,0))) -> Monthly | L30: 17600 | M30: 17600 | P30: 17600
A31: 42 | B31: AWS Marketplace - CyberCX | C31: Netskope Enterprise Browser + Support (1500 licenses) | D31: Cyber | E31: Simon Cowley | F31: 514HDO | G31: 8200 | H31: Fixed | K31: =IF(OR(I31="",J31=""),"Monthly",IF(J31<I31,0,(YEAR(J31)-YEAR(I31))*12+(MONTH(J31)-MONTH(I31))+1-IF(DAY(J31)<DAY(I31),1,0))) -> Monthly | L31: 33416.688 | M31: 33416.688 | P31: 33416.688
A32: FY27B | B32: AWS Marketplace - CyberCX | C32: Netskope Enterprise Browser + Support (2500 @ USD16 per license) | D32: Cyber | E32: Simon Cowley | F32: 514HDO | G32: 8200 | H32: Fixed | K32: =IF(OR(I32="",J32=""),"Monthly",IF(J32<I32,0,(YEAR(J32)-YEAR(I32))*12+(MONTH(J32)-MONTH(I32))+1-IF(DAY(J32)<DAY(I32),1,0))) -> Monthly | L32: 64000 | M32: 64000 | P32: 64000
A33: 41 | B33: AWS Marketplace - CyberCX | C33: Netskope SASE Licences + Support (6500 licenses) | D33: Cyber | E33: Simon Cowley | F33: 514HDO | G33: 8200 | H33: Fixed | K33: =IF(OR(I33="",J33=""),"Monthly",IF(J33<I33,0,(YEAR(J33)-YEAR(I33))*12+(MONTH(J33)-MONTH(I33))+1-IF(DAY(J33)<DAY(I33),1,0))) -> Monthly | L33: 919193.6 | M33: 919193.6 | P33: 919193.6
A34: 43 | B34: AWS Marketplace – Docker Inc | C34: SW subscription Docker Business Plan | D34: Tech | E34: Neeraja/Santhosh | F34: 516HDO | G34: 8200 | H34: Fixed | I34: 45775 | J34: 46139 | K34: =IF(OR(I34="",J34=""),"",IF(J34<I34,0,(YEAR(J34)-YEAR(I34))*12+(MONTH(J34)-MONTH(I34))+1-IF(DAY(J34)<DAY(I34),1,0))) -> 12 | L34: 23040 | M34: 302.92932 | P34: 23040
